ERROR 2025-04-08 14:36:33,013 views 35170 6199078912 Error processing video: UNIQUE constraint failed: videos_video.youtube_id
Traceback (most recent call last):
  File "/Users/muhozayekoye/myyoutube-processor/venv/lib/python3.13/site-packages/django/db/backends/utils.py", line 105, in _execute
    return self.cursor.execute(sql, params)
           ~~~~~~~~~~~~~~~~~~~^^^^^^^^^^^^^
  File "/Users/muhozayekoye/myyoutube-processor/venv/lib/python3.13/site-packages/django/db/backends/sqlite3/base.py", line 360, in execute
    return super().execute(query, params)
           ~~~~~~~~~~~~~~~^^^^^^^^^^^^^^^
sqlite3.IntegrityError: UNIQUE constraint failed: videos_video.youtube_id

The above exception was the direct cause of the following exception:

Traceback (most recent call last):
  File "/Users/muhozayekoye/myyoutube-processor/src/videos/views.py", line 60, in form_valid
    response = super().form_valid(form)
  File "/Users/muhozayekoye/myyoutube-processor/venv/lib/python3.13/site-packages/django/views/generic/edit.py", line 133, in form_valid
    self.object = form.save()
                  ~~~~~~~~~^^
  File "/Users/muhozayekoye/myyoutube-processor/venv/lib/python3.13/site-packages/django/forms/models.py", line 554, in save
    self.instance.save()
    ~~~~~~~~~~~~~~~~~~^^
  File "/Users/muhozayekoye/myyoutube-processor/src/videos/models.py", line 88, in save
    super().save(*args, **kwargs)
    ~~~~~~~~~~~~^^^^^^^^^^^^^^^^^
  File "/Users/muhozayekoye/myyoutube-processor/venv/lib/python3.13/site-packages/django/db/models/base.py", line 902, in save
    self.save_base(
    ~~~~~~~~~~~~~~^
        using=using,
        ^^^^^^^^^^^^
    ...<2 lines>...
        update_fields=update_fields,
        ^^^^^^^^^^^^^^^^^^^^^^^^^^^^
    )
    ^
  File "/Users/muhozayekoye/myyoutube-processor/venv/lib/python3.13/site-packages/django/db/models/base.py", line 1008, in save_base
    updated = self._save_table(
        raw,
    ...<4 lines>...
        update_fields,
    )
  File "/Users/muhozayekoye/myyoutube-processor/venv/lib/python3.13/site-packages/django/db/models/base.py", line 1169, in _save_table
    results = self._do_insert(
        cls._base_manager, using, fields, returning_fields, raw
    )
  File "/Users/muhozayekoye/myyoutube-processor/venv/lib/python3.13/site-packages/django/db/models/base.py", line 1210, in _do_insert
    return manager._insert(
           ~~~~~~~~~~~~~~~^
        [self],
        ^^^^^^^
    ...<3 lines>...
        raw=raw,
        ^^^^^^^^
    )
    ^
  File "/Users/muhozayekoye/myyoutube-processor/venv/lib/python3.13/site-packages/django/db/models/manager.py", line 87, in manager_method
    return getattr(self.get_queryset(), name)(*args, **kwargs)
           ~~~~~~~~~~~~~~~~~~~~~~~~~~~~~~~~~~^^^^^^^^^^^^^^^^^
  File "/Users/muhozayekoye/myyoutube-processor/venv/lib/python3.13/site-packages/django/db/models/query.py", line 1854, in _insert
    return query.get_compiler(using=using).execute_sql(returning_fields)
           ~~~~~~~~~~~~~~~~~~~~~~~~~~~~~~~~~~~~~~~~~~~^^^^^^^^^^^^^^^^^^
  File "/Users/muhozayekoye/myyoutube-processor/venv/lib/python3.13/site-packages/django/db/models/sql/compiler.py", line 1881, in execute_sql
    cursor.execute(sql, params)
    ~~~~~~~~~~~~~~^^^^^^^^^^^^^
  File "/Users/muhozayekoye/myyoutube-processor/venv/lib/python3.13/site-packages/django/db/backends/utils.py", line 122, in execute
    return super().execute(sql, params)
           ~~~~~~~~~~~~~~~^^^^^^^^^^^^^
  File "/Users/muhozayekoye/myyoutube-processor/venv/lib/python3.13/site-packages/django/db/backends/utils.py", line 79, in execute
    return self._execute_with_wrappers(
           ~~~~~~~~~~~~~~~~~~~~~~~~~~~^
        sql, params, many=False, executor=self._execute
        ^^^^^^^^^^^^^^^^^^^^^^^^^^^^^^^^^^^^^^^^^^^^^^^
    )
    ^
  File "/Users/muhozayekoye/myyoutube-processor/venv/lib/python3.13/site-packages/django/db/backends/utils.py", line 92, in _execute_with_wrappers
    return executor(sql, params, many, context)
  File "/Users/muhozayekoye/myyoutube-processor/venv/lib/python3.13/site-packages/django/db/backends/utils.py", line 100, in _execute
    with self.db.wrap_database_errors:
         ^^^^^^^^^^^^^^^^^^^^^^^^^^^^
  File "/Users/muhozayekoye/myyoutube-processor/venv/lib/python3.13/site-packages/django/db/utils.py", line 91, in __exit__
    raise dj_exc_value.with_traceback(traceback) from exc_value
  File "/Users/muhozayekoye/myyoutube-processor/venv/lib/python3.13/site-packages/django/db/backends/utils.py", line 105, in _execute
    return self.cursor.execute(sql, params)
           ~~~~~~~~~~~~~~~~~~~^^^^^^^^^^^^^
  File "/Users/muhozayekoye/myyoutube-processor/venv/lib/python3.13/site-packages/django/db/backends/sqlite3/base.py", line 360, in execute
    return super().execute(query, params)
           ~~~~~~~~~~~~~~~^^^^^^^^^^^^^^^
django.db.utils.IntegrityError: UNIQUE constraint failed: videos_video.youtube_id
ERROR 2025-04-08 16:46:34,538 tasks 68760 6341865472 Error processing video 5: Object of type FetchedTranscript is not JSON serializable
Traceback (most recent call last):
  File "/Users/muhozayekoye/myyoutube-processor/venv/lib/python3.13/site-packages/django/db/models/query.py", line 946, in get_or_create
    return self.get(**kwargs), False
           ~~~~~~~~^^^^^^^^^^
  File "/Users/muhozayekoye/myyoutube-processor/venv/lib/python3.13/site-packages/django/db/models/query.py", line 633, in get
    raise self.model.DoesNotExist(
        "%s matching query does not exist." % self.model._meta.object_name
    )
videos.models.Transcript.DoesNotExist: Transcript matching query does not exist.

During handling of the above exception, another exception occurred:

Traceback (most recent call last):
  File "/Users/muhozayekoye/myyoutube-processor/src/videos/tasks.py", line 52, in process_video
    transcript, created = Transcript.objects.update_or_create(
                          ~~~~~~~~~~~~~~~~~~~~~~~~~~~~~~~~~~~^
        video=video,
        ^^^^^^^^^^^^
    ...<5 lines>...
        }
        ^
    )
    ^
  File "/Users/muhozayekoye/myyoutube-processor/venv/lib/python3.13/site-packages/django/db/models/manager.py", line 87, in manager_method
    return getattr(self.get_queryset(), name)(*args, **kwargs)
           ~~~~~~~~~~~~~~~~~~~~~~~~~~~~~~~~~~^^^^^^^^^^^^^^^^^
  File "/Users/muhozayekoye/myyoutube-processor/venv/lib/python3.13/site-packages/django/db/models/query.py", line 988, in update_or_create
    obj, created = self.select_for_update().get_or_create(
                   ~~~~~~~~~~~~~~~~~~~~~~~~~~~~~~~~~~~~~~^
        create_defaults, **kwargs
        ^^^^^^^^^^^^^^^^^^^^^^^^^
    )
    ^
  File "/Users/muhozayekoye/myyoutube-processor/venv/lib/python3.13/site-packages/django/db/models/query.py", line 953, in get_or_create
    return self.create(**params), True
           ~~~~~~~~~~~^^^^^^^^^^
  File "/Users/muhozayekoye/myyoutube-processor/venv/lib/python3.13/site-packages/django/db/models/query.py", line 663, in create
    obj.save(force_insert=True, using=self.db)
    ~~~~~~~~^^^^^^^^^^^^^^^^^^^^^^^^^^^^^^^^^^
  File "/Users/muhozayekoye/myyoutube-processor/venv/lib/python3.13/site-packages/django/db/models/base.py", line 902, in save
    self.save_base(
    ~~~~~~~~~~~~~~^
        using=using,
        ^^^^^^^^^^^^
    ...<2 lines>...
        update_fields=update_fields,
        ^^^^^^^^^^^^^^^^^^^^^^^^^^^^
    )
    ^
  File "/Users/muhozayekoye/myyoutube-processor/venv/lib/python3.13/site-packages/django/db/models/base.py", line 1008, in save_base
    updated = self._save_table(
        raw,
    ...<4 lines>...
        update_fields,
    )
  File "/Users/muhozayekoye/myyoutube-processor/venv/lib/python3.13/site-packages/django/db/models/base.py", line 1169, in _save_table
    results = self._do_insert(
        cls._base_manager, using, fields, returning_fields, raw
    )
  File "/Users/muhozayekoye/myyoutube-processor/venv/lib/python3.13/site-packages/django/db/models/base.py", line 1210, in _do_insert
    return manager._insert(
           ~~~~~~~~~~~~~~~^
        [self],
        ^^^^^^^
    ...<3 lines>...
        raw=raw,
        ^^^^^^^^
    )
    ^
  File "/Users/muhozayekoye/myyoutube-processor/venv/lib/python3.13/site-packages/django/db/models/manager.py", line 87, in manager_method
    return getattr(self.get_queryset(), name)(*args, **kwargs)
           ~~~~~~~~~~~~~~~~~~~~~~~~~~~~~~~~~~^^^^^^^^^^^^^^^^^
  File "/Users/muhozayekoye/myyoutube-processor/venv/lib/python3.13/site-packages/django/db/models/query.py", line 1854, in _insert
    return query.get_compiler(using=using).execute_sql(returning_fields)
           ~~~~~~~~~~~~~~~~~~~~~~~~~~~~~~~~~~~~~~~~~~~^^^^^^^^^^^^^^^^^^
  File "/Users/muhozayekoye/myyoutube-processor/venv/lib/python3.13/site-packages/django/db/models/sql/compiler.py", line 1880, in execute_sql
    for sql, params in self.as_sql():
                       ~~~~~~~~~~~^^
  File "/Users/muhozayekoye/myyoutube-processor/venv/lib/python3.13/site-packages/django/db/models/sql/compiler.py", line 1805, in as_sql
    self.prepare_value(field, self.pre_save_val(field, obj))
    ~~~~~~~~~~~~~~~~~~^^^^^^^^^^^^^^^^^^^^^^^^^^^^^^^^^^^^^^
  File "/Users/muhozayekoye/myyoutube-processor/venv/lib/python3.13/site-packages/django/db/models/sql/compiler.py", line 1740, in prepare_value
    return field.get_db_prep_save(value, connection=self.connection)
           ~~~~~~~~~~~~~~~~~~~~~~^^^^^^^^^^^^^^^^^^^^^^^^^^^^^^^^^^^
  File "/Users/muhozayekoye/myyoutube-processor/venv/lib/python3.13/site-packages/django/db/models/fields/json.py", line 118, in get_db_prep_save
    return super().get_db_prep_save(value, connection)
           ~~~~~~~~~~~~~~~~~~~~~~~~^^^^^^^^^^^^^^^^^^^
  File "/Users/muhozayekoye/myyoutube-processor/venv/lib/python3.13/site-packages/django/db/models/fields/__init__.py", line 1012, in get_db_prep_save
    return self.get_db_prep_value(value, connection=connection, prepared=False)
           ~~~~~~~~~~~~~~~~~~~~~~^^^^^^^^^^^^^^^^^^^^^^^^^^^^^^^^^^^^^^^^^^^^^^
  File "/Users/muhozayekoye/myyoutube-processor/venv/lib/python3.13/site-packages/django/db/models/fields/json.py", line 102, in get_db_prep_value
    return connection.ops.adapt_json_value(value, self.encoder)
           ~~~~~~~~~~~~~~~~~~~~~~~~~~~~~~~^^^^^^^^^^^^^^^^^^^^^
  File "/Users/muhozayekoye/myyoutube-processor/venv/lib/python3.13/site-packages/django/db/backends/base/operations.py", line 598, in adapt_json_value
    return json.dumps(value, cls=encoder)
           ~~~~~~~~~~^^^^^^^^^^^^^^^^^^^^
  File "/opt/homebrew/Cellar/python@3.13/3.13.2/Frameworks/Python.framework/Versions/3.13/lib/python3.13/json/__init__.py", line 231, in dumps
    return _default_encoder.encode(obj)
           ~~~~~~~~~~~~~~~~~~~~~~~^^^^^
  File "/opt/homebrew/Cellar/python@3.13/3.13.2/Frameworks/Python.framework/Versions/3.13/lib/python3.13/json/encoder.py", line 200, in encode
    chunks = self.iterencode(o, _one_shot=True)
  File "/opt/homebrew/Cellar/python@3.13/3.13.2/Frameworks/Python.framework/Versions/3.13/lib/python3.13/json/encoder.py", line 261, in iterencode
    return _iterencode(o, 0)
  File "/opt/homebrew/Cellar/python@3.13/3.13.2/Frameworks/Python.framework/Versions/3.13/lib/python3.13/json/encoder.py", line 180, in default
    raise TypeError(f'Object of type {o.__class__.__name__} '
                    f'is not JSON serializable')
TypeError: Object of type FetchedTranscript is not JSON serializable
ERROR 2025-04-09 04:29:58,092 ollama_utils 27844 6149369856 Error generating summary with Ollama: model "mistral-small3.1" not found, try pulling it first (status code: 404)
ERROR 2025-04-09 04:30:39,010 ollama_utils 27844 6149369856 Error generating summary with Ollama: model "mistral-small3.1" not found, try pulling it first (status code: 404)
ERROR 2025-04-09 04:31:03,128 ollama_utils 27844 6166196224 Error generating summary with Ollama: model "mistral-small3.1" not found, try pulling it first (status code: 404)
ERROR 2025-04-09 04:31:28,701 ollama_utils 27844 12901707776 Error generating summary with Ollama: model "mistral-small3.1" not found, try pulling it first (status code: 404)
ERROR 2025-04-09 04:32:16,063 ollama_utils 27844 6149369856 Error generating summary with Ollama: model "mistral-small3.1" not found, try pulling it first (status code: 404)
ERROR 2025-04-09 04:32:58,901 ollama_utils 27844 6149369856 Error generating summary with Ollama: model "mistral-small3.1" not found, try pulling it first (status code: 404)
ERROR 2025-04-09 04:33:11,160 ollama_utils 27844 6149369856 Error generating summary with Ollama: model "mistral-small3.1" not found, try pulling it first (status code: 404)
ERROR 2025-04-09 04:44:13,301 ollama_utils 31419 12901707776 Error generating summary with Ollama: llama runner process has terminated: this model is not supported by your version of Ollama. You may need to upgrade (status code: 500)
ERROR 2025-04-09 04:44:27,322 ollama_utils 31419 12901707776 Error generating summary with Ollama: llama runner process has terminated: this model is not supported by your version of Ollama. You may need to upgrade (status code: 500)
ERROR 2025-04-09 04:45:17,717 ollama_utils 31419 12901707776 Error generating summary with Ollama: llama runner process has terminated: this model is not supported by your version of Ollama. You may need to upgrade (status code: 500)
ERROR 2025-04-09 04:45:30,640 ollama_utils 31419 12901707776 Error generating summary with Ollama: llama runner process has terminated: this model is not supported by your version of Ollama. You may need to upgrade (status code: 500)
ERROR 2025-04-09 04:46:27,461 ollama_utils 31419 12901707776 Error generating summary with Ollama: llama runner process has terminated: this model is not supported by your version of Ollama. You may need to upgrade (status code: 500)
ERROR 2025-04-09 04:47:12,155 ollama_utils 31419 12901707776 Error generating summary with Ollama: llama runner process has terminated: this model is not supported by your version of Ollama. You may need to upgrade (status code: 500)
ERROR 2025-04-09 04:48:03,070 ollama_utils 31419 12901707776 Error generating summary with Ollama: llama runner process has terminated: this model is not supported by your version of Ollama. You may need to upgrade (status code: 500)
ERROR 2025-04-09 04:49:38,551 ollama_utils 31419 12901707776 Error generating summary with Ollama: llama runner process has terminated: this model is not supported by your version of Ollama. You may need to upgrade (status code: 500)
