ERROR 2025-04-08 14:36:33,013 views 35170 6199078912 Error processing video: UNIQUE constraint failed: videos_video.youtube_id
Traceback (most recent call last):
  File "/Users/muhozayekoye/myyoutube-processor/venv/lib/python3.13/site-packages/django/db/backends/utils.py", line 105, in _execute
    return self.cursor.execute(sql, params)
           ~~~~~~~~~~~~~~~~~~~^^^^^^^^^^^^^
  File "/Users/muhozayekoye/myyoutube-processor/venv/lib/python3.13/site-packages/django/db/backends/sqlite3/base.py", line 360, in execute
    return super().execute(query, params)
           ~~~~~~~~~~~~~~~^^^^^^^^^^^^^^^
sqlite3.IntegrityError: UNIQUE constraint failed: videos_video.youtube_id

The above exception was the direct cause of the following exception:

Traceback (most recent call last):
  File "/Users/muhozayekoye/myyoutube-processor/src/videos/views.py", line 60, in form_valid
    response = super().form_valid(form)
  File "/Users/muhozayekoye/myyoutube-processor/venv/lib/python3.13/site-packages/django/views/generic/edit.py", line 133, in form_valid
    self.object = form.save()
                  ~~~~~~~~~^^
  File "/Users/muhozayekoye/myyoutube-processor/venv/lib/python3.13/site-packages/django/forms/models.py", line 554, in save
    self.instance.save()
    ~~~~~~~~~~~~~~~~~~^^
  File "/Users/muhozayekoye/myyoutube-processor/src/videos/models.py", line 88, in save
    super().save(*args, **kwargs)
    ~~~~~~~~~~~~^^^^^^^^^^^^^^^^^
  File "/Users/muhozayekoye/myyoutube-processor/venv/lib/python3.13/site-packages/django/db/models/base.py", line 902, in save
    self.save_base(
    ~~~~~~~~~~~~~~^
        using=using,
        ^^^^^^^^^^^^
    ...<2 lines>...
        update_fields=update_fields,
        ^^^^^^^^^^^^^^^^^^^^^^^^^^^^
    )
    ^
  File "/Users/muhozayekoye/myyoutube-processor/venv/lib/python3.13/site-packages/django/db/models/base.py", line 1008, in save_base
    updated = self._save_table(
        raw,
    ...<4 lines>...
        update_fields,
    )
  File "/Users/muhozayekoye/myyoutube-processor/venv/lib/python3.13/site-packages/django/db/models/base.py", line 1169, in _save_table
    results = self._do_insert(
        cls._base_manager, using, fields, returning_fields, raw
    )
  File "/Users/muhozayekoye/myyoutube-processor/venv/lib/python3.13/site-packages/django/db/models/base.py", line 1210, in _do_insert
    return manager._insert(
           ~~~~~~~~~~~~~~~^
        [self],
        ^^^^^^^
    ...<3 lines>...
        raw=raw,
        ^^^^^^^^
    )
    ^
  File "/Users/muhozayekoye/myyoutube-processor/venv/lib/python3.13/site-packages/django/db/models/manager.py", line 87, in manager_method
    return getattr(self.get_queryset(), name)(*args, **kwargs)
           ~~~~~~~~~~~~~~~~~~~~~~~~~~~~~~~~~~^^^^^^^^^^^^^^^^^
  File "/Users/muhozayekoye/myyoutube-processor/venv/lib/python3.13/site-packages/django/db/models/query.py", line 1854, in _insert
    return query.get_compiler(using=using).execute_sql(returning_fields)
           ~~~~~~~~~~~~~~~~~~~~~~~~~~~~~~~~~~~~~~~~~~~^^^^^^^^^^^^^^^^^^
  File "/Users/muhozayekoye/myyoutube-processor/venv/lib/python3.13/site-packages/django/db/models/sql/compiler.py", line 1881, in execute_sql
    cursor.execute(sql, params)
    ~~~~~~~~~~~~~~^^^^^^^^^^^^^
  File "/Users/muhozayekoye/myyoutube-processor/venv/lib/python3.13/site-packages/django/db/backends/utils.py", line 122, in execute
    return super().execute(sql, params)
           ~~~~~~~~~~~~~~~^^^^^^^^^^^^^
  File "/Users/muhozayekoye/myyoutube-processor/venv/lib/python3.13/site-packages/django/db/backends/utils.py", line 79, in execute
    return self._execute_with_wrappers(
           ~~~~~~~~~~~~~~~~~~~~~~~~~~~^
        sql, params, many=False, executor=self._execute
        ^^^^^^^^^^^^^^^^^^^^^^^^^^^^^^^^^^^^^^^^^^^^^^^
    )
    ^
  File "/Users/muhozayekoye/myyoutube-processor/venv/lib/python3.13/site-packages/django/db/backends/utils.py", line 92, in _execute_with_wrappers
    return executor(sql, params, many, context)
  File "/Users/muhozayekoye/myyoutube-processor/venv/lib/python3.13/site-packages/django/db/backends/utils.py", line 100, in _execute
    with self.db.wrap_database_errors:
         ^^^^^^^^^^^^^^^^^^^^^^^^^^^^
  File "/Users/muhozayekoye/myyoutube-processor/venv/lib/python3.13/site-packages/django/db/utils.py", line 91, in __exit__
    raise dj_exc_value.with_traceback(traceback) from exc_value
  File "/Users/muhozayekoye/myyoutube-processor/venv/lib/python3.13/site-packages/django/db/backends/utils.py", line 105, in _execute
    return self.cursor.execute(sql, params)
           ~~~~~~~~~~~~~~~~~~~^^^^^^^^^^^^^
  File "/Users/muhozayekoye/myyoutube-processor/venv/lib/python3.13/site-packages/django/db/backends/sqlite3/base.py", line 360, in execute
    return super().execute(query, params)
           ~~~~~~~~~~~~~~~^^^^^^^^^^^^^^^
django.db.utils.IntegrityError: UNIQUE constraint failed: videos_video.youtube_id
